"""O módulo `exceptions.py` apenas declara a exceção `RelatorioError`."""


class RelatorioError(Exception):
    pass
